Workbook

Sheet Página32
A1: Máquina | B1: Operação | C1: Item Atual | D1: Ferramental Atual | E1: Próximo Item | F1: Ferramental do Próximo Item
A2: 15-973 | B2: Afiação | C2: 320127 | D2: {=CONCATENATE(_xlfn.XLOOKUP(C2,'Banco De Rebolos'!A:A,'Banco De Rebolos'!D:D), " ",_xlfn.XLOOKUP(C2,'Banco De Rebolos'!A:A,'Banco De Rebolos'!B:B), " e ",_xlfn.XLOOKUP(C2,'Banco De Rebolos'!A:A,'Banco De Rebolos'!C:C))} -> Dedicado REB.1 e REB.2 | E2: 318846 | F2: {=CONCATENATE(_xlfn.XLOOKUP(E2,'Banco De Rebolos'!A:A,'Banco De Rebolos'!D:D), " ",_xlfn.XLOOKUP(E2,'Banco De Rebolos'!A:A,'Banco De Rebolos'!B:B), " e ",_xlfn.XLOOKUP(E2,'Banco De Rebolos'!A:A,'Banco De Rebolos'!C:C))} -> Universal REB.U55 e REB.U65 | K2: Demais horarios
A3: 24-761 | B3: Afiação | C3: 340795 | D3: {=CONCATENATE(_xlfn.XLOOKUP(C3,'Banco De Rebolos'!A:A,'Banco De Rebolos'!D:D), " ",_xlfn.XLOOKUP(C3,'Banco De Rebolos'!A:A,'Banco De Rebolos'!B:B), " e ",_xlfn.XLOOKUP(C3,'Banco De Rebolos'!A:A,'Banco De Rebolos'!C:C))} -> Universal REB.U80 e REB.U90 | E3: 318848 | F3: {=CONCATENATE(_xlfn.XLOOKUP(E3,'Banco De Rebolos'!A:A,'Banco De Rebolos'!D:D), " ",_xlfn.XLOOKUP(E3,'Banco De Rebolos'!A:A,'Banco De Rebolos'!B:B), " e ",_xlfn.XLOOKUP(E3,'Banco De Rebolos'!A:A,'Banco De Rebolos'!C:C))} -> Universal REB.U55 e REB.U65
A4: 26-635 | B4: Afiação | C4: 319630 | D4: {=CONCATENATE(_xlfn.XLOOKUP(C4,'Banco De Rebolos'!A:A,'Banco De Rebolos'!D:D), " ",_xlfn.XLOOKUP(C4,'Banco De Rebolos'!A:A,'Banco De Rebolos'!B:B), " e ",_xlfn.XLOOKUP(C4,'Banco De Rebolos'!A:A,'Banco De Rebolos'!C:C))} -> Universal REB.U55 e REB.U65 | E4: 325689 | F4: {=CONCATENATE(_xlfn.XLOOKUP(E4,'Banco De Rebolos'!A:A,'Banco De Rebolos'!D:D), " ",_xlfn.XLOOKUP(E4,'Banco De Rebolos'!A:A,'Banco De Rebolos'!B:B), " e ",_xlfn.XLOOKUP(E4,'Banco De Rebolos'!A:A,'Banco De Rebolos'!C:C))} -> Universal REB.U55 e REB.U65
A5: 30-161 | B5: Afiação | C5: 320234 | D5: {=CONCATENATE(_xlfn.XLOOKUP(C5,'Banco De Rebolos'!A:A,'Banco De Rebolos'!D:D), " ",_xlfn.XLOOKUP(C5,'Banco De Rebolos'!A:A,'Banco De Rebolos'!B:B), " e ",_xlfn.XLOOKUP(C5,'Banco De Rebolos'!A:A,'Banco De Rebolos'!C:C))} -> Dedicado REB.1 e REB.2 | E5: 325689 | F5: {=CONCATENATE(_xlfn.XLOOKUP(E5,'Banco De Rebolos'!A:A,'Banco De Rebolos'!D:D), " ",_xlfn.XLOOKUP(E5,'Banco De Rebolos'!A:A,'Banco De Rebolos'!B:B), " e ",_xlfn.XLOOKUP(E5,'Banco De Rebolos'!A:A,'Banco De Rebolos'!C:C))} -> Universal REB.U55 e REB.U65 | L5: .

Sheet Página34
A1: Está concatenando para obter informações e trensferir para , Texto Material, Tempo Setup e Peça
A2: 316620
A3: 318489
A4: 318490
A5: 318491
A6: 318492
A7: 318493
A8: 318494
A9: 318495
A10: 318496
A11: 318497
A12: 318498
A13: 318499
... A490: 343752
A491: 103.071-1
A492: 343885
A493: 343877
A494: 343879
A495: 343881
A496: 343883
A497: 343891
A498: 343893
A499: 343895
A500: 343897
A501: 354720
A502: 354721
A503: 354723
... A507: 354727

Sheet Banco De Rebolos
A1: Item | B1: Rebolo | C1: Rebolo 2 | D1: Tipo
A2: 316561 | B2: REB.U90 | C2: - | D2: =IF(B2="Reb.1","Dedicado","Universal") -> Universal
A3: 316563 | B3: REB.U90 | C3: - | D3: =IF(B3="Reb.1","Dedicado","Universal") -> Universal
A4: 316590 | B4: REB.U67 | C4: - | D4: =IF(B4="Reb.1","Dedicado","Universal") -> Universal
A5: 316601 | B5: REB.1 | C5: REB.2 | D5: =IF(B5="Reb.1","Dedicado","Universal") -> Dedicado
A6: 316601 | B6: REB.1 | C6: REB.2 | D6: =IF(B6="Reb.1","Dedicado","Universal") -> Dedicado
A7: 316604 | B7: REB.U80 | C7: REB.U68 | D7: =IF(B7="Reb.1","Dedicado","Universal") -> Universal
A8: 316616 | B8: REB.U68 | C8: - | D8: =IF(B8="Reb.1","Dedicado","Universal") -> Universal
A9: 316616 | B9: REB.U68 | C9: - | D9: =IF(B9="Reb.1","Dedicado","Universal") -> Universal
A10: 316636 | B10: REB.U90 | C10: - | D10: =IF(B10="Reb.1","Dedicado","Universal") -> Universal
A11: 316868 | B11: REB.U80 | C11: REB.U90 | D11: =IF(B11="Reb.1","Dedicado","Universal") -> Universal
A12: 316897 | B12: REB.1 | C12: REB.2 | D12: =IF(B12="Reb.1","Dedicado","Universal") -> Dedicado
A13: 316905 | B13: REB.1 | C13: REB.2 | D13: =IF(B13="Reb.1","Dedicado","Universal") -> Dedicado
... A49: 318836 | B49: REB.U55 | C49: REB.U65 | D49: =IF(B49="Reb.1","Dedicado","Universal") -> Universal
A50: 318837 | B50: REB.1 | C50: REB.2 | D50: Dedicado
A51: 318838 | B51: REB.U44 | C51: - | D51: =IF(B51="Reb.1","Dedicado","Universal") -> Universal
A52: 318838 | B52: REB.U44 | C52: - | D52: =IF(B52="Reb.1","Dedicado","Universal") -> Universal
A53: 318839 | B53: REB.U44 | C53: - | D53: =IF(B53="Reb.1","Dedicado","Universal") -> Universal
A54: 318839 | B54: REB.U44 | C54: - | D54: =IF(B54="Reb.1","Dedicado","Universal") -> Universal
A55: 318840 | B55: REB.U44 | C55: - | D55: =IF(B55="Reb.1","Dedicado","Universal") -> Universal
A56: 318840 | B56: REB.U44 | C56: - | D56: =IF(B56="Reb.1","Dedicado","Universal") -> Universal
A57: 318841 | B57: REB.U44 | C57: - | D57: =IF(B57="Reb.1","Dedicado","Universal") -> Universal
A58: 318841 | B58: REB.U44 | C58: - | D58: =IF(B58="Reb.1","Dedicado","Universal") -> Universal
A59: 318842 | B59: REB.U44 | C59: - | D59: =IF(B59="Reb.1","Dedicado","Universal") -> Universal
A60: 318842 | B60: REB.U44 | C60: - | D60: =IF(B60="Reb.1","Dedicado","Universal") -> Universal
A61: 318844 | B61: REB.U55 | C61: REB.U65 | D61: =IF(B61="Reb.1","Dedicado","Universal") -> Universal
A62: 318846 | B62: REB.U55 | C62: REB.U65 | D62: =IF(B62="Reb.1","Dedicado","Universal") -> Universal
... A450: 343753 | B450: REB.U68 | C450: - | D450: =IF(B450="Reb.1","Dedicado","Universal") -> Universal
A451: 103.026-1 | B451: REB.U68 | C451: - | D451: =IF(B451="Reb.1","Dedicado","Universal") -> Universal
A452: 103.026-1 | B452: REB.U68 | C452: - | D452: =IF(B452="Reb.1","Dedicado","Universal") -> Universal
A453: 103.027-1 | B453: REB.U68 | C453: - | D453: =IF(B453="Reb.1","Dedicado","Universal") -> Universal
A454: 103.027-1 | B454: REB.U68 | C454: - | D454: =IF(B454="Reb.1","Dedicado","Universal") -> Universal
A455: 103.028-1 | B455: REB.U68 | C455: - | D455: =IF(B455="Reb.1","Dedicado","Universal") -> Universal
A456: 103.028-1 | B456: REB.U68 | C456: - | D456: =IF(B456="Reb.1","Dedicado","Universal") -> Universal
A457: 103.030-1 | B457: REB.U90 | C457: - | D457: =IF(B457="Reb.1","Dedicado","Universal") -> Universal
A458: 103.042-1 | B458: REB.1 | C458: REB.2 | D458: =IF(B458="Reb.1","Dedicado","Universal") -> Dedicado
A459: 103.042-1 | B459: REB.1 | C459: REB.2 | D459: =IF(B459="Reb.1","Dedicado","Universal") -> Dedicado
A460: 103.043-1 | B460: REB.1 | C460: REB.2 | D460: =IF(B460="Reb.1","Dedicado","Universal") -> Dedicado
A461: 103.043-1 | B461: REB.1 | C461: REB.2 | D461: =IF(B461="Reb.1","Dedicado","Universal") -> Dedicado
A462: 103.044-1 | B462: REB.1 | C462: REB.2 | D462: =IF(B462="Reb.1","Dedicado","Universal") -> Dedicado
...

Sheet Dados_Incompletos
A1: Origem (Aba) | B1: Localização | C1: Máquina | D1: Motivo
A2: Retificas | B2: Linha 2 | C2: 05-903 | D2: Sem Data (Ignorado)
A3: Retificas | B3: Linha 5 | C3: 09-815 | D3: Sem Data (Ignorado)
A4: Retificas | B4: Linha 6 | C4: 10-817 | D4: Sem Data (Ignorado)
A5: Retificas | B5: Linha 9 | C5: 13-969 | D5: Sem Data (Ignorado)
A6: Retificas | B6: Linha 13 | C6: 18-925 | D6: Sem Data (Ignorado)
A7: Retificas | B7: Linha 17 | C7: 22-916 | D7: Sem Data (Ignorado)
A8: Retificas | B8: Linha 25 | C8: 30-786 | D8: Sem Data (Ignorado)
A9: Retificas | B9: Linha 26 | C9: 31-806 | D9: Sem Data (Ignorado)
A10: Retificas | B10: Linha 28 | C10: 33-807 | D10: Sem Data (Ignorado)
A11: Retificas | B11: Linha 33 | C11: 38-881 | D11: Sem Data (Ignorado)
A12: Retificas | B12: Linha 36 | C12: 41/na | D12: Sem Data (Ignorado)
... A57: Afiadoras | B57: Linha 43 | C57: Não informada | D57: Sem Data (Ignorado)

Sheet Proximos_A_Tirar_Tempo
A1: Origem (Aba) | B1: Máquina | C1: Data | D1: Horário Estimado | E1: Turno Destino
A2: Retificas | B2: 07-267 | C2: 46225 | D2: 0.45833333 | E2: Turno 1
A3: Retificas | B3: 08-086 | C3: 46225 | D3: 0.29166667 | E3: Turno 1
A4: Retificas | B4: 11-363 | C4: 46227 | D4: 0.29166667 | E4: Turno 1
A5: Retificas | B5: 12-962 | C5: 46225 | D5: 0.40625 | E5: Turno 1
A6: Retificas | B6: 14-971 | C6: 46225 | D6: 0.38194444 | E6: Turno 1
A7: Retificas | B7: 15-977 | C7: 46226 | D7: 0.33333333 | E7: Turno 1
A8: Retificas | B8: 20-927 | C8: 46225 | D8: 0.41666667 | E8: Turno 1
A9: Retificas | B9: 24-259 | C9: 46226 | D9: 0.33333333 | E9: Turno 1
A10: Retificas | B10: 25-258 | C10: 46225 | D10: 0.5625 | E10: Turno 1
A11: Retificas | B11: 35-842 | C11: 46225 | D11: 0.40972222 | E11: Turno 1
A12: Retificas | B12: 36-854 | C12: 46225 | D12: 0.33333333 | E12: Turno 1
A13: Retificas | B13: 40-912 | C13: 46225 | D13: 0.27777778 | E13: Turno 1
... A22: Afiadoras | B22: 40-142 | C22: 46225 | D22: 0.36388889 | E22: Turno 1

Sheet Rebolos Afiadoras
A1: MAQUINA | B1: REBOLO | C1: DATA DA TROCA | D1: DATA PARA TROCAR
A2: 04-427
A3: 06-868 | B3: U44
A4: 07-743
A5: 08-247
A6: 09-088
A7: 10-812
A8: 11-365
A9: 12-367
A10: 13-964
A11: 14-967
A12: 15-973
A13: 16-975
A14: 17-140
A15: 18-957
... A25: 28-432

Sheet Página14

Sheet Página6
A2: AFIADORAS
A3: Máquinas: | B3: 04-427 | C3: 06-868 | D3: 07-743 | E3: 08-247 | F3: 09-088 | G3: 10-812 | H3: 11-365 | I3: 12-367 | J3: 13-964 | K3: 14-967 | L3: 15-973 | M3: 16-975 | N3: 17-140 | O3: 18-957 | P3: 19-760 | Q3: 20-774 | R3: 21-206 | S3: 22-813
A4: Hrs De Parada: | B4: 0.625 | C4: 0.025694444 | D4: 0.84166667 | E4: 0.78263889 | F4: 0.0625 | G4: 0.50277778 | H4: 0.11805556 | I4: 0.45833333 | J4: 0.89166667 | K4: 0.19722222 | L4: 0.67361111 | M4: 0.78125 | N4: 0.6625 | O4: MANUTENÇÃO | P4: 0.36111111 | Q4: 0.63194444 | R4: 0.31041667 | S4: 0.86180556
A5: Data | B5: 45445 | C5: 45445 | D5: 45444 | E5: 45445 | F5: 45445 | G5: 45445 | H5: 45445 | I5: 45446 | J5: 45444 | K5: 45445 | L5: 45444 | M5: 45444 | N5: 45445 | O5: 0-jan | P5: 45414 | Q5: 45444 | R5: 45445 | S5: 45444
A6: Operação: | B6: Afiação | C6: Afiação | D6: Afiação | E6: Afiação | F6: Afiação | G6: Afiação | H6: Afiação | I6: Afiação | J6: Afiação | K6: Afiação | L6: Afiação | M6: Afiação | N6: Afiação | O6: Afiação | P6: Afiação | Q6: Afiação | R6: Afiação | S6: Afiação
A7: Final da Ordem: | B7: 6415 | C7: 297 | D7: 2428 | E7: 7693 | F7: 2566 | G7: 2454 | H7: 6424 | I7: 3295 | J7: 5474 | K7: 3294 | L7: 1803 | M7: 6641 | N7: 9524 | O7: 3433 | P7: 7354 | Q7: 5476 | R7: 6430 | S7: 5475
A8: Item: | B8: 320019 | C8: 318839 | D8: 320249 | E8: 318818 | F8: 318826 | G8: 327279 | H8: 320240 | I8: 320121 | J8: 338951 | K8: 318825 | L8: 338144 | M8: 338662 | N8: 318829 | O8: 327274 | P8: 319630 | Q8: 341266 | R8: 338683 | S8: 0
A9: Próx Item: | B9: 0 | C9: 0 | D9: 327278 | E9: 0 | F9: 0 | G9: 0 | H9: 0 | I9: 0 | J9: 0 | K9: 0 | L9: 341218 | M9: 341240 | N9: 0 | O9: 0 | P9: 0 | Q9: 0 | R9: 0 | S9: 342306
A10: Próx Ordem: | B10: 0 | C10: 0 | D10: 3977 | E10: 0 | F10: 0 | G10: 0 | H10: 0 | I10: 0 | J10: 0 | K10: 0 | L10: 6429 | M10: 6968 | N10: 0 | O10: 0 | P10: 0 | Q10: 7777 | R10: 0 | S10: 4798
A11: Troca de Rebolo: | B11: 45453 | C11: 45450 | D11: 45443 | E11: 45448 | F11: 45453 | G11: 45444 | H11: 45446 | I11: 45452 | J11: 45450 | K11: 45449 | L11: 45452 | M11: 45455 | N11: 45449 | O11: 45449 | P11: 45453 | Q11: 45445 | R11: ? | S11: ?
A12: Montagem: | B12: 0 | C12: 0 | D12: 0 | E12: 0 | F12: 0 | G12: 0 | H12: 0 | I12: 0 | J12: OK | K12: 0 | L12: OK | M12: OK | N12: 0 | O12: 0 | P12: 0 | Q12: OK | R12: 0 | S12: OK
D13: seq | F13: seq

Sheet Página7
